Workbook

Sheet TO PAY
A1: Name | B1: To Pay | C1: Paid? | D1: WS notes
A2: Adam Harris | B2: =Breakdown!K2 -> 16 | C2: Yes
A3: Adam Mills | B3: =Breakdown!K3 -> 204 | C3: Yes | F3: PAYMENT INFO
A4: Alex Newsham | B4: =Breakdown!K4 -> 12 | C4: Yes | F4: Account Name | G4: Cambridge University Hockey Club
A5: Alex Rontgen | B5: =Breakdown!K5 -> 8 | C5: Yes | F5: Account Number | G5: 72372762
A6: Alex Warren | B6: =Breakdown!K6 -> 143 | C6: Yes | F6: Sort Code | G6: 40-16-08
A7: Andi Kapounek | B7: =Breakdown!K7 -> 173.2 | C7: Yes | F7: Reference | G7: msubsINITIALSURNAME (eg msubsWSTUBBS)
A8: Archie Jenkins | B8: =Breakdown!K8 -> 302.19 | C8: Yes | F8: Due Date | G8: 8th January - late fines of £1/day after this
A9: Ben Crook | B9: =Breakdown!K9 -> 284.2 | C9: Yes | F9: All information can be found on email - contact ws418 if any issues :)
A10: Ben James | B10: =Breakdown!K10 -> 92.5 | C10: Yes
A11: Ben Tremblay | B11: =Breakdown!K11 -> 101 | C11: Yes | F11: Summary
A12: Benedict Holder | B12: =Breakdown!K12 -> 80.5 | C12: Yes | F12: Total | G12: =sum('TO PAY'!B2:B100) -> 9493.38
A13: Callum Wolvers | B13: =Breakdown!K13 -> 68.5 | C13: Yes | F13: Amount paid | G13: =SUMIF('TO PAY'!C2:C99,"Yes",'TO PAY'!B2:B99) -> 9358.38
A14: Calum Brown | B14: =Breakdown!K14 -> 10 | C14: Yes | F14: Amount outstanding | G14: =SUMIF('TO PAY'!C2:C100,"No",'TO PAY'!B2:B100) -> 135
A15: Calum Stevenson | B15: =Breakdown!K15 -> 204 | C15: Yes | F15: People paid | G15: =85-G16 -> 84
A16: Campbell Mackenzie | B16: =Breakdown!K16 -> 192 | C16: Yes | F16: People to pay | G16: =COUNTIF('TO PAY'!C2:C100,"No") -> 1
A17: Casey Mear | B17: =Breakdown!K17 -> 306.2 | C17: Yes | F17: Correct as of | G17: 46008.604
A18: Charles Waddington | B18: =Breakdown!K18 -> 92.5 | C18: Yes
A19: Chris Batten | B19: =Breakdown!K19 -> 76.5 | C19: Yes
A20: Chris Gibson | B20: =Breakdown!K20 -> 93.92 | C20: Yes
A21: Connor Singleton | B21: =Breakdown!K21 -> 78 | C21: Yes
A22: David Gee | B22: =Breakdown!K22 -> 192 | C22: Yes
A23: Don Lee | B23: =Breakdown!K23 -> 264.2 | C23: Yes
A24: Dylan Meacher-Nisbet | B24: =Breakdown!K24 -> 122 | C24: Yes
A25: Ed Timberlake | B25: =Breakdown!K25 -> 240 | C25: Yes
A26: Erik Van Kesteren | B26: =Breakdown!K26 -> 0 | C26: Yes
A27: Felix McClean | B27: =Breakdown!K27 -> 156.7 | C27: Yes
A28: Femi Owolade-Coombes | B28: =Breakdown!K28 -> -5.1 | C28: Yes | D28: Take off Lent subs
A29: Finn Dovey | B29: =Breakdown!K29 -> 88.5 | C29: Yes
A30: Finn Macare | B30: =Breakdown!K30 -> 216 | C30: Yes
A31: Fred Dickson | B31: =Breakdown!K31 -> 208 | C31: Yes
A32: Freddie Arbuthnott | B32: =Breakdown!K32 -> 22.9 | C32: Yes
A33: Freddie McElwaine-Johnn | B33: =Breakdown!K33 -> 161.7 | C33: Yes | D33: Chased
A34: Gabriel Haselhurst | B34: =Breakdown!K34 -> 153.5 | C34: Yes | D34: Paid 155
A35: George Cooper | B35: =Breakdown!K35 -> 261.68 | C35: Yes
A36: Harry Bannister | B36: =Breakdown!K36 -> 148.7 | C36: Yes
A37: Harry Neal | B37: =Breakdown!K37 -> 72.5 | C37: Yes
A38: Henry Forrest | B38: =Breakdown!K38 -> 68.5 | C38: Yes
A39: Henry Means | B39: =Breakdown!K39 -> 28 | C39: Yes
A40: Henry Murphy | B40: =Breakdown!K40 -> 106.5 | C40: Yes
...

Sheet Breakdown
A1: Name | B1: Base Rate | C1: League Fees | D1: BUCS fees | E1: Travel reimb | F1: Umpire reimb | G1: Kit | H1: Saxon | I1: Y1 | J1: Misc | K1: Total | L1: WS notes | N1: Already paid returner subs
A2: Adam Harris | C2: ='League fees'!G2 -> 16 | D2: ='BUCS fees'!E2 -> 0 | E2: =IFERROR(VLOOKUP(A2, Travel!$A$2:$B$99, 2, FALSE), "") | F2: =IFERROR(VLOOKUP(A2, Umpiring!$A$2:$C$100, 2, FALSE), "") | G2: ='CUMHC Kit'!E2 | H2: =IFERROR(VLOOKUP(A2, 'Saxon Order'!$A$2:$C$100, 2, FALSE), "") | I2: =IFERROR(VLOOKUP(A2, 'Y1 order'!$A$2:$D$100, 2, FALSE), "") | K2: =SUM(B2:J2) -> 16 | N2: Alex Newsham
A3: Adam Mills | B3: =IF(ISNUMBER(MATCH(A3, $N$2:$N$99, 0)), "", 85) -> 85 | C3: ='League fees'!G3 -> 32 | D3: ='BUCS fees'!E3 -> 0 | E3: =IFERROR(VLOOKUP(A3, Travel!$A$2:$B$99, 2, FALSE), "") | F3: =IFERROR(VLOOKUP(A3, Umpiring!$A$2:$C$100, 2, FALSE), "") | G3: ='CUMHC Kit'!E3 -> 87 | H3: =IFERROR(VLOOKUP(A3, 'Saxon Order'!$A$2:$C$100, 2, FALSE), "") | I3: =IFERROR(VLOOKUP(A3, 'Y1 order'!$A$2:$D$100, 2, FALSE), "") | K3: =SUM(B3:J3) -> 204 | N3: Alex Warren
A4: Alex Newsham | B4: =IF(ISNUMBER(MATCH(A4, $N$2:$N$99, 0)), "", 85) | C4: ='League fees'!G4 -> 12 | D4: ='BUCS fees'!E4 -> 0 | E4: =IFERROR(VLOOKUP(A4, Travel!$A$2:$B$99, 2, FALSE), "") | F4: =IFERROR(VLOOKUP(A4, Umpiring!$A$2:$C$100, 2, FALSE), "") | G4: ='CUMHC Kit'!E4 -> 0 | H4: =IFERROR(VLOOKUP(A4, 'Saxon Order'!$A$2:$C$100, 2, FALSE), "") | I4: =IFERROR(VLOOKUP(A4, 'Y1 order'!$A$2:$D$100, 2, FALSE), "") | K4: =SUM(B4:J4) -> 12 | N4: Andi Kapounek
A5: Alex Rontgen | B5: =IF(ISNUMBER(MATCH(A5, $N$2:$N$99, 0)), "", 85) -> 85 | C5: ='League fees'!G5 -> 8 | D5: ='BUCS fees'!E5 -> 0 | E5: =IFERROR(VLOOKUP(A5, Travel!$A$2:$B$99, 2, FALSE), "") | F5: =IFERROR(VLOOKUP(A5, Umpiring!$A$2:$C$100, 2, FALSE), "") | G5: ='CUMHC Kit'!E5 -> 0 | H5: =IFERROR(VLOOKUP(A5, 'Saxon Order'!$A$2:$C$100, 2, FALSE), "") | I5: =IFERROR(VLOOKUP(A5, 'Y1 order'!$A$2:$D$100, 2, FALSE), "") | J5: -85 | K5: =SUM(B5:J5) -> 8 | L5: didn't train | N5: Ben James
A6: Alex Warren | B6: =IF(ISNUMBER(MATCH(A6, $N$2:$N$99, 0)), "", 85) | C6: ='League fees'!G6 -> 48 | D6: ='BUCS fees'!E6 -> 30 | E6: =IFERROR(VLOOKUP(A6, Travel!$A$2:$B$99, 2, FALSE), "") | F6: =IFERROR(VLOOKUP(A6, Umpiring!$A$2:$C$100, 2, FALSE), "") | G6: ='CUMHC Kit'!E6 -> 65 | H6: =IFERROR(VLOOKUP(A6, 'Saxon Order'!$A$2:$C$100, 2, FALSE), "") | I6: =IFERROR(VLOOKUP(A6, 'Y1 order'!$A$2:$D$100, 2, FALSE), "") | K6: =SUM(B6:J6) -> 143 | N6: Benedict Holder
A7: Andi Kapounek | B7: =IF(ISNUMBER(MATCH(A7, $N$2:$N$99, 0)), "", 85) | C7: ='League fees'!G7 -> 28 | D7: ='BUCS fees'!E7 -> 24 | E7: =IFERROR(VLOOKUP(A7, Travel!$A$2:$B$99, 2, FALSE), "") | F7: =IFERROR(VLOOKUP(A7, Umpiring!$A$2:$C$100, 2, FALSE), "") | G7: ='CUMHC Kit'!E7 -> 65 | H7: =IFERROR(VLOOKUP(A7, 'Saxon Order'!$A$2:$C$100, 2, FALSE), "") -> 56.2 | I7: =IFERROR(VLOOKUP(A7, 'Y1 order'!$A$2:$D$100, 2, FALSE), "") | K7: =SUM(B7:J7) -> 173.2 | N7: Callum Wolvers
A8: Archie Jenkins | B8: =IF(ISNUMBER(MATCH(A8, $N$2:$N$99, 0)), "", 85) -> 85 | C8: ='League fees'!G8 -> 32 | D8: ='BUCS fees'!E8 -> 4 | E8: =IFERROR(VLOOKUP(A8, Travel!$A$2:$B$99, 2, FALSE), "") | F8: =IFERROR(VLOOKUP(A8, Umpiring!$A$2:$C$100, 2, FALSE), "") | G8: ='CUMHC Kit'!E8 -> 87 | H8: =IFERROR(VLOOKUP(A8, 'Saxon Order'!$A$2:$C$100, 2, FALSE), "") -> 56.2 | I8: =IFERROR(VLOOKUP(A8, 'Y1 order'!$A$2:$D$100, 2, FALSE), "") -> 37.99 | K8: =SUM(B8:J8) -> 302.19 | N8: Charles Waddington
A9: Ben Crook | B9: =IF(ISNUMBER(MATCH(A9, $N$2:$N$99, 0)), "", 85) -> 85 | C9: ='League fees'!G9 -> 52 | D9: ='BUCS fees'!E9 -> 4 | E9: =IFERROR(VLOOKUP(A9, Travel!$A$2:$B$99, 2, FALSE), "") | F9: =IFERROR(VLOOKUP(A9, Umpiring!$A$2:$C$100, 2, FALSE), "") | G9: ='CUMHC Kit'!E9 -> 87 | H9: =IFERROR(VLOOKUP(A9, 'Saxon Order'!$A$2:$C$100, 2, FALSE), "") -> 56.2 | I9: =IFERROR(VLOOKUP(A9, 'Y1 order'!$A$2:$D$100, 2, FALSE), "") | K9: =SUM(B9:J9) -> 284.2 | N9: Chris Batten
A10: Ben James | B10: =IF(ISNUMBER(MATCH(A10, $N$2:$N$99, 0)), "", 85) | C10: ='League fees'!G10 -> 40 | D10: ='BUCS fees'!E10 -> 20 | E10: =IFERROR(VLOOKUP(A10, Travel!$A$2:$B$99, 2, FALSE), "") | F10: =IFERROR(VLOOKUP(A10, Umpiring!$A$2:$C$100, 2, FALSE), "") | G10: ='CUMHC Kit'!E10 -> 32.5 | H10: =IFERROR(VLOOKUP(A10, 'Saxon Order'!$A$2:$C$100, 2, FALSE), "") | I10: =IFERROR(VLOOKUP(A10, 'Y1 order'!$A$2:$D$100, 2, FALSE), "") | K10: =SUM(B10:J10) -> 92.5 | N10: Connor Singleton
A11: Ben Tremblay | B11: =IF(ISNUMBER(MATCH(A11, $N$2:$N$99, 0)), "", 85) -> 85 | C11: ='League fees'!G11 -> 16 | D11: ='BUCS fees'!E11 -> 0 | E11: =IFERROR(VLOOKUP(A11, Travel!$A$2:$B$99, 2, FALSE), "") | F11: =IFERROR(VLOOKUP(A11, Umpiring!$A$2:$C$100, 2, FALSE), "") | G11: ='CUMHC Kit'!E11 -> 0 | H11: =IFERROR(VLOOKUP(A11, 'Saxon Order'!$A$2:$C$100, 2, FALSE), "") | I11: =IFERROR(VLOOKUP(A11, 'Y1 order'!$A$2:$D$100, 2, FALSE), "") | K11: =SUM(B11:J11) -> 101 | N11: Felix McClean
A12: Benedict Holder | B12: =IF(ISNUMBER(MATCH(A12, $N$2:$N$99, 0)), "", 85) | C12: ='League fees'!G12 -> 48 | D12: ='BUCS fees'!E12 -> 0 | E12: =IFERROR(VLOOKUP(A12, Travel!$A$2:$B$99, 2, FALSE), "") | F12: =IFERROR(VLOOKUP(A12, Umpiring!$A$2:$C$100, 2, FALSE), "") | G12: ='CUMHC Kit'!E12 -> 32.5 | H12: =IFERROR(VLOOKUP(A12, 'Saxon Order'!$A$2:$C$100, 2, FALSE), "") | I12: =IFERROR(VLOOKUP(A12, 'Y1 order'!$A$2:$D$100, 2, FALSE), "") | K12: =SUM(B12:J12) -> 80.5 | N12: Femi Owolade-Coombes
A13: Callum Wolvers | B13: =IF(ISNUMBER(MATCH(A13, $N$2:$N$99, 0)), "", 85) | C13: ='League fees'!G13 -> 20 | D13: ='BUCS fees'!E13 -> 16 | E13: =IFERROR(VLOOKUP(A13, Travel!$A$2:$B$99, 2, FALSE), "") | F13: =IFERROR(VLOOKUP(A13, Umpiring!$A$2:$C$100, 2, FALSE), "") | G13: ='CUMHC Kit'!E13 -> 32.5 | H13: =IFERROR(VLOOKUP(A13, 'Saxon Order'!$A$2:$C$100, 2, FALSE), "") | I13: =IFERROR(VLOOKUP(A13, 'Y1 order'!$A$2:$D$100, 2, FALSE), "") | K13: =SUM(B13:J13) -> 68.5 | N13: Finn Dovey
A14: Calum Brown | C14: ='League fees'!G14 -> 0 | D14: ='BUCS fees'!E14 -> 10 | E14: =IFERROR(VLOOKUP(A14, Travel!$A$2:$B$99, 2, FALSE), "") | F14: =IFERROR(VLOOKUP(A14, Umpiring!$A$2:$C$100, 2, FALSE), "") | G14: ='CUMHC Kit'!E14 -> 0 | H14: =IFERROR(VLOOKUP(A14, 'Saxon Order'!$A$2:$C$100, 2, FALSE), "") | I14: =IFERROR(VLOOKUP(A14, 'Y1 order'!$A$2:$D$100, 2, FALSE), "") | K14: =SUM(B14:J14) -> 10 | N14: Freddie Arbuthnott
A15: Calum Stevenson | B15: =IF(ISNUMBER(MATCH(A15, $N$2:$N$99, 0)), "", 85) -> 85 | C15: ='League fees'!G15 -> 32 | D15: ='BUCS fees'!E15 -> 0 | E15: =IFERROR(VLOOKUP(A15, Travel!$A$2:$B$99, 2, FALSE), "") | F15: =IFERROR(VLOOKUP(A15, Umpiring!$A$2:$C$100, 2, FALSE), "") | G15: ='CUMHC Kit'!E15 -> 87 | H15: =IFERROR(VLOOKUP(A15, 'Saxon Order'!$A$2:$C$100, 2, FALSE), "") | I15: =IFERROR(VLOOKUP(A15, 'Y1 order'!$A$2:$D$100, 2, FALSE), "") | K15: =SUM(B15:J15) -> 204 | N15: Freddie McElwaine-Johnn
A16: Campbell Mackenzie | B16: =IF(ISNUMBER(MATCH(A16, $N$2:$N$99, 0)), "", 85) -> 85 | C16: ='League fees'!G16 -> 20 | D16: ='BUCS fees'!E16 -> 0 | E16: =IFERROR(VLOOKUP(A16, Travel!$A$2:$B$99, 2, FALSE), "") | F16: =IFERROR(VLOOKUP(A16, Umpiring!$A$2:$C$100, 2, FALSE), "") | G16: ='CUMHC Kit'!E16 -> 87 | H16: =IFERROR(VLOOKUP(A16, 'Saxon Order'!$A$2:$C$100, 2, FALSE), "") | I16: =IFERROR(VLOOKUP(A16, 'Y1 order'!$A$2:$D$100, 2, FALSE), "") | K16: =SUM(B16:J16) -> 192 | N16: Freddie Ogilvie
A17: Casey Mear | B17: =IF(ISNUMBER(MATCH(A17, $N$2:$N$99, 0)), "", 85) -> 85 | C17: ='League fees'!G17 -> 48 | D17: ='BUCS fees'!E17 -> 30 | E17: =IFERROR(VLOOKUP(A17, Travel!$A$2:$B$99, 2, FALSE), "") | F17: =IFERROR(VLOOKUP(A17, Umpiring!$A$2:$C$100, 2, FALSE), "") | G17: ='CUMHC Kit'!E17 -> 87 | H17: =IFERROR(VLOOKUP(A17, 'Saxon Order'!$A$2:$C$100, 2, FALSE), "") -> 56.2 | I17: =IFERROR(VLOOKUP(A17, 'Y1 order'!$A$2:$D$100, 2, FALSE), "") | K17: =SUM(B17:J17) -> 306.2 | N17: Harry Bannister
A18: Charles Waddington | B18: =IF(ISNUMBER(MATCH(A18, $N$2:$N$99, 0)), "", 85) | C18: ='League fees'!G18 -> 40 | D18: ='BUCS fees'!E18 -> 20 | E18: =IFERROR(VLOOKUP(A18, Travel!$A$2:$B$99, 2, FALSE), "") | F18: =IFERROR(VLOOKUP(A18, Umpiring!$A$2:$C$100, 2, FALSE), "") | G18: ='CUMHC Kit'!E18 -> 32.5 | H18: =IFERROR(VLOOKUP(A18, 'Saxon Order'!$A$2:$C$100, 2, FALSE), "") | I18: =IFERROR(VLOOKUP(A18, 'Y1 order'!$A$2:$D$100, 2, FALSE), "") | K18: =SUM(B18:J18) -> 92.5 | N18: Harry Neal
A19: Chris Batten | B19: =IF(ISNUMBER(MATCH(A19, $N$2:$N$99, 0)), "", 85) | C19: ='League fees'!G19 -> 44 | D19: ='BUCS fees'!E19 -> 0 | E19: =IFERROR(VLOOKUP(A19, Travel!$A$2:$B$99, 2, FALSE), "") | F19: =IFERROR(VLOOKUP(A19, Umpiring!$A$2:$C$100, 2, FALSE), "") | G19: ='CUMHC Kit'!E19 -> 32.5 | H19: =IFERROR(VLOOKUP(A19, 'Saxon Order'!$A$2:$C$100, 2, FALSE), "") | I19: =IFERROR(VLOOKUP(A19, 'Y1 order'!$A$2:$D$100, 2, FALSE), "") | K19: =SUM(B19:J19) -> 76.5 | N19: Henry Forrest
A20: Chris Gibson | B20: =IF(ISNUMBER(MATCH(A20, $N$2:$N$99, 0)), "", 85) -> 85 | C20: ='League fees'!G20 -> 24 | D20: ='BUCS fees'!E20 -> 16 | E20: -31.08 | F20: =IFERROR(VLOOKUP(A20, Umpiring!$A$2:$C$100, 2, FALSE), "") | G20: ='CUMHC Kit'!E20 -> 0 | H20: =IFERROR(VLOOKUP(A20, 'Saxon Order'!$A$2:$C$100, 2, FALSE), "") | I20: =IFERROR(VLOOKUP(A20, 'Y1 order'!$A$2:$D$100, 2, FALSE), "") | K20: =SUM(B20:I20) -> 93.92 | L20: for Wandies taxis | N20: Henry Means
A21: Connor Singleton | B21: =IF(ISNUMBER(MATCH(A21, $N$2:$N$99, 0)), "", 85) | C21: ='League fees'!G21 -> 44 | D21: ='BUCS fees'!E21 -> 29 | E21: =IFERROR(VLOOKUP(A21, Travel!$A$2:$B$99, 2, FALSE), "") | F21: =IFERROR(VLOOKUP(A21, Umpiring!$A$2:$C$100, 2, FALSE), "") -> -60 | G21: ='CUMHC Kit'!E21 -> 65 | H21: =IFERROR(VLOOKUP(A21, 'Saxon Order'!$A$2:$C$100, 2, FALSE), "") | I21: =IFERROR(VLOOKUP(A21, 'Y1 order'!$A$2:$D$100, 2, FALSE), "") | K21: =SUM(B21:J21) -> 78 | N21: Henry Murphy
A22: David Gee | B22: =IF(ISNUMBER(MATCH(A22, $N$2:$N$99, 0)), "", 85) -> 85 | C22: ='League fees'!G22 -> 20 | D22: ='BUCS fees'!E22 -> 0 | E22: =IFERROR(VLOOKUP(A22, Travel!$A$2:$B$99, 2, FALSE), "") | F22: =IFERROR(VLOOKUP(A22, Umpiring!$A$2:$C$100, 2, FALSE), "") | G22: ='CUMHC Kit'!E22 -> 87 | H22: =IFERROR(VLOOKUP(A22, 'Saxon Order'!$A$2:$C$100, 2, FALSE), "") | I22: =IFERROR(VLOOKUP(A22, 'Y1 order'!$A$2:$D$100, 2, FALSE), "") | K22: =SUM(B22:J22) -> 192 | N22: James Cake
A23: Don Lee | B23: =IF(ISNUMBER(MATCH(A23, $N$2:$N$99, 0)), "", 85) -> 85 | C23: ='League fees'!G23 -> 36 | D23: ='BUCS fees'!E23 -> 0 | E23: =IFERROR(VLOOKUP(A23, Travel!$A$2:$B$99, 2, FALSE), "") | F23: =IFERROR(VLOOKUP(A23, Umpiring!$A$2:$C$100, 2, FALSE), "") | G23: ='CUMHC Kit'!E23 -> 87 | H23: =IFERROR(VLOOKUP(A23, 'Saxon Order'!$A$2:$C$100, 2, FALSE), "") -> 56.2 | I23: =IFERROR(VLOOKUP(A23, 'Y1 order'!$A$2:$D$100, 2, FALSE), "") | K23: =SUM(B23:J23) -> 264.2 | N23: James McKinlay-Smith
A24: Dylan Meacher-Nisbet | B24: =IF(ISNUMBER(MATCH(A24, $N$2:$N$99, 0)), "", 85) -> 85 | C24: ='League fees'!G24 -> 36 | D24: ='BUCS fees'!E24 -> 0 | E24: =IFERROR(VLOOKUP(A24, Travel!$A$2:$B$99, 2, FALSE), "") | F24: =IFERROR(VLOOKUP(A24, Umpiring!$A$2:$C$100, 2, FALSE), "") | G24: ='CUMHC Kit'!E24 -> 0 | H24: =IFERROR(VLOOKUP(A24, 'Saxon Order'!$A$2:$C$100, 2, FALSE), "") | I24: =IFERROR(VLOOKUP(A24, 'Y1 order'!$A$2:$D$100, 2, FALSE), "") | J24: 1 | K24: =SUM(B24:J24) -> 122 | L24: Late fine | N24: Jamie Carruthers
A25: Ed Timberlake | B25: =IF(ISNUMBER(MATCH(A25, $N$2:$N$99, 0)), "", 85) -> 85 | C25: ='League fees'!G25 -> 40 | D25: ='BUCS fees'!E25 -> 28 | E25: =IFERROR(VLOOKUP(A25, Travel!$A$2:$B$99, 2, FALSE), "") | F25: =IFERROR(VLOOKUP(A25, Umpiring!$A$2:$C$100, 2, FALSE), "") | G25: ='CUMHC Kit'!E25 -> 87 | H25: =IFERROR(VLOOKUP(A25, 'Saxon Order'!$A$2:$C$100, 2, FALSE), "") | I25: =IFERROR(VLOOKUP(A25, 'Y1 order'!$A$2:$D$100, 2, FALSE), "") | K25: =SUM(B25:J25) -> 240 | N25: Joe Greer
A26: Erik Van Kesteren | C26: ='League fees'!G26 -> 4 | D26: ='BUCS fees'!E26 -> 0 | E26: =IFERROR(VLOOKUP(A26, Travel!$A$2:$B$99, 2, FALSE), "") | F26: =IFERROR(VLOOKUP(A26, Umpiring!$A$2:$C$100, 2, FALSE), "") | G26: ='CUMHC Kit'!E26 -> 0 | H26: =IFERROR(VLOOKUP(A26, 'Saxon Order'!$A$2:$C$100, 2, FALSE), "") | I26: =IFERROR(VLOOKUP(A26, 'Y1 order'!$A$2:$D$100, 2, FALSE), "") | J26: -4 | K26: =SUM(B26:J26) -> 0 | L26: reimbursed | N26: Joe Conway
A27: Felix McClean | B27: =IF(ISNUMBER(MATCH(A27, $N$2:$N$99, 0)), "", 85) | C27: ='League fees'!G27 -> 44 | D27: ='BUCS fees'!E27 -> 24 | E27: =IFERROR(VLOOKUP(A27, Travel!$A$2:$B$99, 2, FALSE), "") | F27: =IFERROR(VLOOKUP(A27, Umpiring!$A$2:$C$100, 2, FALSE), "") | G27: ='CUMHC Kit'!E27 -> 32.5 | H27: =IFERROR(VLOOKUP(A27, 'Saxon Order'!$A$2:$C$100, 2, FALSE), "") -> 56.2 | I27: =IFERROR(VLOOKUP(A27, 'Y1 order'!$A$2:$D$100, 2, FALSE), "") | K27: =SUM(B27:J27) -> 156.7 | N27: Joseph Preddy
A28: Femi Owolade-Coombes | B28: =IF(ISNUMBER(MATCH(A28, $N$2:$N$99, 0)), "", 85) | C28: ='League fees'!G28 -> 28 | D28: ='BUCS fees'!E28 -> 25 | E28: =IFERROR(VLOOKUP(A28, Travel!$A$2:$B$99, 2, FALSE), "") -> -90.6 | F28: =IFERROR(VLOOKUP(A28, Umpiring!$A$2:$C$100, 2, FALSE), "") | G28: ='CUMHC Kit'!E28 -> 32.5 | H28: =IFERROR(VLOOKUP(A28, 'Saxon Order'!$A$2:$C$100, 2, FALSE), "") | I28: =IFERROR(VLOOKUP(A28, 'Y1 order'!$A$2:$D$100, 2, FALSE), "") | K28: =SUM(B28:J28) -> -5.1 | N28: Kyrill Borzenko
A29: Finn Dovey | B29: =IF(ISNUMBER(MATCH(A29, $N$2:$N$99, 0)), "", 85) | C29: ='League fees'!G29 -> 48 | D29: ='BUCS fees'!E29 -> 8 | E29: =IFERROR(VLOOKUP(A29, Travel!$A$2:$B$99, 2, FALSE), "") | F29: =IFERROR(VLOOKUP(A29, Umpiring!$A$2:$C$100, 2, FALSE), "") | G29: ='CUMHC Kit'!E29 -> 32.5 | H29: =IFERROR(VLOOKUP(A29, 'Saxon Order'!$A$2:$C$100, 2, FALSE), "") | I29: =IFERROR(VLOOKUP(A29, 'Y1 order'!$A$2:$D$100, 2, FALSE), "") | K29: =SUM(B29:J29) -> 88.5 | N29: Leo Parry-Wingfield
A30: Finn Macare | B30: =IF(ISNUMBER(MATCH(A30, $N$2:$N$99, 0)), "", 85) -> 85 | C30: ='League fees'!G30 -> 44 | D30: ='BUCS fees'!E30 -> 0 | E30: =IFERROR(VLOOKUP(A30, Travel!$A$2:$B$99, 2, FALSE), "") | F30: =IFERROR(VLOOKUP(A30, Umpiring!$A$2:$C$100, 2, FALSE), "") | G30: ='CUMHC Kit'!E30 -> 87 | H30: =IFERROR(VLOOKUP(A30, 'Saxon Order'!$A$2:$C$100, 2, FALSE), "") | I30: =IFERROR(VLOOKUP(A30, 'Y1 order'!$A$2:$D$100, 2, FALSE), "") | K30: =SUM(B30:J30) -> 216 | N30: Matt Vennard
A31: Fred Dickson | B31: =IF(ISNUMBER(MATCH(A31, $N$2:$N$99, 0)), "", 85) -> 85 | C31: ='League fees'!G31 -> 36 | D31: ='BUCS fees'!E31 -> 0 | E31: =IFERROR(VLOOKUP(A31, Travel!$A$2:$B$99, 2, FALSE), "") | F31: =IFERROR(VLOOKUP(A31, Umpiring!$A$2:$C$100, 2, FALSE), "") | G31: ='CUMHC Kit'!E31 -> 87 | H31: =IFERROR(VLOOKUP(A31, 'Saxon Order'!$A$2:$C$100, 2, FALSE), "") | I31: =IFERROR(VLOOKUP(A31, 'Y1 order'!$A$2:$D$100, 2, FALSE), "") | K31: =SUM(B31:J31) -> 208 | N31: Oliver Knight
A32: Freddie Arbuthnott | B32: =IF(ISNUMBER(MATCH(A32, $N$2:$N$99, 0)), "", 85) | C32: ='League fees'!G32 -> 44 | D32: ='BUCS fees'!E32 -> 20 | E32: =IFERROR(VLOOKUP(A32, Travel!$A$2:$B$99, 2, FALSE), "") -> -73.6 | F32: =IFERROR(VLOOKUP(A32, Umpiring!$A$2:$C$100, 2, FALSE), "") | G32: ='CUMHC Kit'!E32 -> 32.5 | H32: =IFERROR(VLOOKUP(A32, 'Saxon Order'!$A$2:$C$100, 2, FALSE), "") | I32: =IFERROR(VLOOKUP(A32, 'Y1 order'!$A$2:$D$100, 2, FALSE), "") | K32: =SUM(B32:J32) -> 22.9 | N32: Ollie West
A33: Freddie McElwaine-Johnn | B33: =IF(ISNUMBER(MATCH(A33, $N$2:$N$99, 0)), "", 85) | C33: ='League fees'!G33 -> 48 | D33: ='BUCS fees'!E33 -> 24 | E33: =IFERROR(VLOOKUP(A33, Travel!$A$2:$B$99, 2, FALSE), "") | F33: =IFERROR(VLOOKUP(A33, Umpiring!$A$2:$C$100, 2, FALSE), "") | G33: ='CUMHC Kit'!E33 -> 32.5 | H33: =IFERROR(VLOOKUP(A33, 'Saxon Order'!$A$2:$C$100, 2, FALSE), "") -> 56.2 | I33: =IFERROR(VLOOKUP(A33, 'Y1 order'!$A$2:$D$100, 2, FALSE), "") | J33: 1 | K33: =SUM(B33:J33) -> 161.7 | L33: Late fine | N33: Ossian Finch
A34: Gabriel Haselhurst | B34: =IF(ISNUMBER(MATCH(A34, $N$2:$N$99, 0)), "", 85) -> 85 | C34: ='League fees'!G34 -> 24 | D34: ='BUCS fees'!E34 -> 0 | E34: =IFERROR(VLOOKUP(A34, Travel!$A$2:$B$99, 2, FALSE), "") | F34: =IFERROR(VLOOKUP(A34, Umpiring!$A$2:$C$100, 2, FALSE), "") | G34: ='CUMHC Kit'!E34 -> 87 | H34: =IFERROR(VLOOKUP(A34, 'Saxon Order'!$A$2:$C$100, 2, FALSE), "") | I34: =IFERROR(VLOOKUP(A34, 'Y1 order'!$A$2:$D$100, 2, FALSE), "") | J34: -42.5 | K34: =SUM(B34:J34) -> 153.5 | L34: illness | N34: Owen Dyson
A35: George Cooper | B35: =IF(ISNUMBER(MATCH(A35, $N$2:$N$99, 0)), "", 85) -> 85 | C35: ='League fees'!G35 -> 12 | D35: ='BUCS fees'!E35 -> 0 | E35: =IFERROR(VLOOKUP(A35, Travel!$A$2:$B$99, 2, FALSE), "") | F35: =IFERROR(VLOOKUP(A35, Umpiring!$A$2:$C$100, 2, FALSE), "") | G35: ='CUMHC Kit'!E35 -> 32.5 | H35: =IFERROR(VLOOKUP(A35, 'Saxon Order'!$A$2:$C$100, 2, FALSE), "") -> 56.2 | I35: =IFERROR(VLOOKUP(A35, 'Y1 order'!$A$2:$D$100, 2, FALSE), "") -> 75.98 | K35: =SUM(B35:J35) -> 261.68 | N35: Peter Jansen
A36: Harry Bannister | B36: =IF(ISNUMBER(MATCH(A36, $N$2:$N$99, 0)), "", 85) | C36: ='League fees'!G36 -> 40 | D36: ='BUCS fees'!E36 -> 20 | E36: =IFERROR(VLOOKUP(A36, Travel!$A$2:$B$99, 2, FALSE), "") | F36: =IFERROR(VLOOKUP(A36, Umpiring!$A$2:$C$100, 2, FALSE), "") | G36: ='CUMHC Kit'!E36 -> 32.5 | H36: =IFERROR(VLOOKUP(A36, 'Saxon Order'!$A$2:$C$100, 2, FALSE), "") -> 56.2 | I36: =IFERROR(VLOOKUP(A36, 'Y1 order'!$A$2:$D$100, 2, FALSE), "") | K36: =SUM(B36:J36) -> 148.7 | N36: Riley Aumonier
A37: Harry Neal | B37: =IF(ISNUMBER(MATCH(A37, $N$2:$N$99, 0)), "", 85) | C37: ='League fees'!G37 -> 40 | D37: ='BUCS fees'!E37 -> 0 | E37: =IFERROR(VLOOKUP(A37, Travel!$A$2:$B$99, 2, FALSE), "") | F37: =IFERROR(VLOOKUP(A37, Umpiring!$A$2:$C$100, 2, FALSE), "") | G37: ='CUMHC Kit'!E37 -> 32.5 | H37: =IFERROR(VLOOKUP(A37, 'Saxon Order'!$A$2:$C$100, 2, FALSE), "") | I37: =IFERROR(VLOOKUP(A37, 'Y1 order'!$A$2:$D$100, 2, FALSE), "") | K37: =SUM(B37:J37) -> 72.5 | N37: Rob Tingle
A38: Henry Forrest | B38: =IF(ISNUMBER(MATCH(A38, $N$2:$N$99, 0)), "", 85) | C38: ='League fees'!G38 -> 36 | D38: ='BUCS fees'!E38 -> 0 | E38: =IFERROR(VLOOKUP(A38, Travel!$A$2:$B$99, 2, FALSE), "") | F38: =IFERROR(VLOOKUP(A38, Umpiring!$A$2:$C$100, 2, FALSE), "") | G38: ='CUMHC Kit'!E38 -> 32.5 | H38: =IFERROR(VLOOKUP(A38, 'Saxon Order'!$A$2:$C$100, 2, FALSE), "") | I38: =IFERROR(VLOOKUP(A38, 'Y1 order'!$A$2:$D$100, 2, FALSE), "") | K38: =SUM(B38:J38) -> 68.5 | N38: Sachin Bhogal
A39: Henry Means | B39: =IF(ISNUMBER(MATCH(A39, $N$2:$N$99, 0)), "", 85) | C39: ='League fees'!G39 -> 28 | D39: ='BUCS fees'!E39 -> 0 | E39: =IFERROR(VLOOKUP(A39, Travel!$A$2:$B$99, 2, FALSE), "") | F39: =IFERROR(VLOOKUP(A39, Umpiring!$A$2:$C$100, 2, FALSE), "") | G39: ='CUMHC Kit'!E39 -> 0 | H39: =IFERROR(VLOOKUP(A39, 'Saxon Order'!$A$2:$C$100, 2, FALSE), "") | I39: =IFERROR(VLOOKUP(A39, 'Y1 order'!$A$2:$D$100, 2, FALSE), "") | K39: =SUM(B39:J39) -> 28 | N39: Sam Featherstone
A40: Henry Murphy | B40: =IF(ISNUMBER(MATCH(A40, $N$2:$N$99, 0)), "", 85) | C40: ='League fees'!G40 -> 44 | D40: ='BUCS fees'!E40 -> 30 | E40: =IFERROR(VLOOKUP(A40, Travel!$A$2:$B$99, 2, FALSE), "") | F40: =IFERROR(VLOOKUP(A40, Umpiring!$A$2:$C$100, 2, FALSE), "") | G40: ='CUMHC Kit'!E40 -> 32.5 | H40: =IFERROR(VLOOKUP(A40, 'Saxon Order'!$A$2:$C$100, 2, FALSE), "") | I40: =IFERROR(VLOOKUP(A40, 'Y1 order'!$A$2:$D$100, 2, FALSE), "") | K40: =SUM(B40:J40) -> 106.5 | N40: Sam Martin
...

Sheet League fees
A1: Player | B1: Blues Saturday | C1: Wandies Saturday | D1: Squandies Saturday | E1: Blundies Saturday | F1: Total Saturday League Appearances | G1: Total Match Fees
A2: Adam Harris | B2: 0 | C2: 0 | D2: 1 | E2: 3 | F2: 4 | G2: =(F2*4) -> 16
A3: Adam Mills | B3: 0 | C3: 0 | D3: 2 | E3: 6 | F3: 8 | G3: =(F3*4) -> 32
A4: Alex Newsham | B4: 0 | C4: 0 | D4: 0 | E4: 3 | F4: 3 | G4: =(F4*4) -> 12
A5: Alex Rontgen | B5: 0 | C5: 0 | D5: 0 | E5: 2 | F5: 2 | G5: =(F5*4) -> 8
A6: Alex Warren | B6: 12 | C6: 0 | D6: 0 | E6: 0 | F6: 12 | G6: =(F6*4) -> 48
A7: Andi Kapounek | B7: 2 | C7: 5 | D7: 0 | E7: 0 | F7: 7 | G7: =(F7*4) -> 28
A8: Archie Jenkins | B8: 0 | C8: 0 | D8: 7 | E8: 1 | F8: 8 | G8: =(F8*4) -> 32
A9: Ben Crook | B9: 0 | C9: 2 | D9: 11 | E9: 0 | F9: 13 | G9: =(F9*4) -> 52
A10: Ben James | B10: 0 | C10: 10 | D10: 0 | E10: 0 | F10: 10 | G10: =(F10*4) -> 40
A11: Ben Tremblay | B11: 0 | C11: 0 | D11: 0 | E11: 4 | F11: 4 | G11: =(F11*4) -> 16
A12: Benedict Holder | B12: 0 | C12: 0 | D12: 0 | E12: 12 | F12: 12 | G12: =(F12*4) -> 48
A13: Callum Wolvers | B13: 0 | C13: 5 | D13: 0 | E13: 0 | F13: 5 | G13: =(F13*4) -> 20
... A86: Zach Fecher | B86: 0 | C86: 1 | D86: 1 | E86: 8 | F86: 10 | G86: =(F86*4) -> 40

Sheet BUCS fees
A1: Player | B1: Blues BUCS | C1: Wandies BUCS | D1: Total BUCS Appearances | E1: Total Match Fees
A2: Adam Harris | B2: 0 | C2: 0 | D2: 0 | E2: =B2*5+C2*4 -> 0
A3: Adam Mills | B3: 0 | C3: 0 | D3: 0 | E3: =B3*5+C3*4 -> 0
A4: Alex Newsham | B4: 0 | C4: 0 | D4: 0 | E4: =B4*5+C4*4 -> 0
A5: Alex Rontgen | B5: 0 | C5: 0 | D5: 0 | E5: =B5*5+C5*4 -> 0
A6: Alex Warren | B6: 6 | C6: 0 | D6: 6 | E6: =B6*5+C6*4 -> 30
A7: Andi Kapounek | B7: 0 | C7: 6 | D7: 6 | E7: =B7*5+C7*4 -> 24
A8: Archie Jenkins | B8: 0 | C8: 1 | D8: 1 | E8: =B8*5+C8*4 -> 4
A9: Ben Crook | B9: 0 | C9: 1 | D9: 1 | E9: =B9*5+C9*4 -> 4
A10: Ben James | B10: 0 | C10: 5 | D10: 5 | E10: =B10*5+C10*4 -> 20
A11: Ben Tremblay | B11: 0 | C11: 0 | D11: 0 | E11: =B11*5+C11*4 -> 0
A12: Benedict Holder | B12: 0 | C12: 0 | D12: 0 | E12: =B12*5+C12*4 -> 0
A13: Callum Wolvers | B13: 0 | C13: 4 | D13: 4 | E13: =B13*5+C13*4 -> 16
... A86: Zach Fecher | B86: 0 | C86: 0 | D86: 0 | E86: =B86*5+C86*4 -> 0

Sheet Travel
A1: Name | B1: Owed
A2: Wilf Stokhuyzen | B2: -162.6
A3: Pete Jansen | B3: =-137-106.1 -> -243.1
A4: James Cake | B4: -103.4
A5: Femi Owolade-Coombes | B5: -90.6
A6: Freddie Arbuthnott | B6: -73.6
A7: Kyrill Borzenko | B7: -11.49
A8: Matt Vennard | B8: -208.8
B10: =SUM(B2:B8) -> -893.59

Sheet Umpiring
A1: Name | B1: Amount owed / £ | C1: Friendlies | D1: BUCS | E1: League | F1: Paid?
A2: Sam Featherstone | B2: -195 | C2: 3 | D2: 4 | E2: 6
A3: Rob Lewis | B3: -300 | C3: 5 | D3: 9 | E3: 6 | F3: Yes
A4: Bev Budd | B4: -210 | C4: 4 | D4: 7 | E4: 3 | F4: Yes
A5: Kyrill Borzenko | B5: -120 | C5: 1 | D5: 3 | E5: 4
A6: Pete Jansen | B6: -15 | C6: 1
A7: Joe Conway | B7: -120 | C7: 2 | E7: 6
A8: Rhys Gibbs | B8: -60 | C8: 1 | E8: 3
A9: Josh Ripley | B9: -60 | D9: 1 | E9: 3 | F9: Yes
A10: Jenna Langley | B10: -45 | D10: 1 | E10: 2 | G10: edited 07/01
A11: Joe Greer | B11: -90 | E11: 6
A12: Wilf Stokhuyzen | B12: -75 | C12: 1 | D12: 1 | E12: 3 | G12: edited 07/01
A13: Sian Rees | B13: -30 | E13: 2
A14: Ian Wilson | B14: -30 | E14: 2 | F14: Yes
A15: Felix Polonius | B15: -15 | E15: 1 | F15: Yes
A16: Sam Pritchard | B16: -45 | E16: 3
A17: Cal Wolvers | B17: -45 | E17: 3
A18: Connor Singleton | B18: -60 | E18: 4
A19: Ossian Finch | B19: -15 | E19: 1
A20: Maia Polonius | B20: -15 | E20: 1 | F20: Yes
A21: Millie Ely | B21: -45 | E21: 3
A22: Jack Childs | B22: -15 | E22: 1 | F22: Yes
A23: James MS | B23: -15 | E23: 1
A24: Katie Jeans | B24: -15 | E24: 1
A26: Total included in subs | B26: =SUM(B2:B24)-B3-B4-B14-B15-B20-B22-B9 -> -990

Sheet CUMHC Kit
A1: Name | B1: Home shirt | C1: Away shirt | D1: Shorts | E1: Total cost
A3: Adam Mills | B3: 1 | C3: 1 | D3: 1 | E3: =(B3+C3)*$H$3+D3*$H$4 -> 87 | G3: Cost of shirt | H3: 32.5
E4: =(B4+C4)*$H$3+D4*$H$4 -> 0 | G4: Cost of shorts | H4: 22
E5: =(B5+C5)*$H$3+D5*$H$4 -> 0
A6: Alex Warren | B6: 1 | C6: 1 | E6: =(B6+C6)*$H$3+D6*$H$4 -> 65
A7: Andi Kapounek | B7: 1 | C7: 1 | E7: =(B7+C7)*$H$3+D7*$H$4 -> 65
A8: Archie Jenkins | B8: 1 | C8: 1 | D8: 1 | E8: =(B8+C8)*$H$3+D8*$H$4 -> 87
A9: Ben Crook | B9: 1 | C9: 1 | D9: 1 | E9: =(B9+C9)*$H$3+D9*$H$4 -> 87
A10: Ben James | B10: 1 | E10: =(B10+C10)*$H$3+D10*$H$4 -> 32.5
A11: Ben Tremblay | E11: =(B11+C11)*$H$3+D11*$H$4 -> 0
A12: Benedict Holder | B12: 1 | E12: =(B12+C12)*$H$3+D12*$H$4 -> 32.5
A13: Callum Wolvers | B13: 1 | E13: =(B13+C13)*$H$3+D13*$H$4 -> 32.5
E14: =(B14+C14)*$H$3+D14*$H$4 -> 0
A15: Calum Stephenson | B15: 1 | C15: 1 | D15: 1 | E15: =(B15+C15)*$H$3+D15*$H$4 -> 87
A16: Campbell Mackenzie | B16: 1 | C16: 1 | D16: 1 | E16: =(B16+C16)*$H$3+D16*$H$4 -> 87
A17: Casey Mear | B17: 1 | C17: 1 | D17: 1 | E17: =(B17+C17)*$H$3+D17*$H$4 -> 87
A18: Charles Waddington | B18: 1 | E18: =(B18+C18)*$H$3+D18*$H$4 -> 32.5
A19: Chris Batten | B19: 1 | E19: =(B19+C19)*$H$3+D19*$H$4 -> 32.5
E20: =(B20+C20)*$H$3+D20*$H$4 -> 0
A21: Connor Singleton | B21: 1 | C21: 1 | E21: =(B21+C21)*$H$3+D21*$H$4 -> 65
A22: David Gee | B22: 1 | C22: 1 | D22: 1 | E22: =(B22+C22)*$H$3+D22*$H$4 -> 87
A23: Don Lee | B23: 1 | C23: 1 | D23: 1 | E23: =(B23+C23)*$H$3+D23*$H$4 -> 87
E24: =(B24+C24)*$H$3+D24*$H$4 -> 0
A25: Ed Timberlake | B25: 1 | C25: 1 | D25: 1 | E25: =(B25+C25)*$H$3+D25*$H$4 -> 87
E26: =(B26+C26)*$H$3+D26*$H$4 -> 0
A27: Felix McClean | B27: 1 | E27: =(B27+C27)*$H$3+D27*$H$4 -> 32.5
A28: Femi Owolade-Coombes | B28: 1 | E28: =(B28+C28)*$H$3+D28*$H$4 -> 32.5
A29: Finn Dovey | B29: 1 | E29: =(B29+C29)*$H$3+D29*$H$4 -> 32.5
A30: Finn Macare | B30: 1 | C30: 1 | D30: 1 | E30: =(B30+C30)*$H$3+D30*$H$4 -> 87
A31: Fred Dickson | B31: 1 | C31: 1 | D31: 1 | E31: =(B31+C31)*$H$3+D31*$H$4 -> 87
A32: Freddie Arbuthnott | B32: 1 | E32: =(B32+C32)*$H$3+D32*$H$4 -> 32.5
A33: Freddie McElwaine-Johnn | B33: 1 | E33: =(B33+C33)*$H$3+D33*$H$4 -> 32.5
A34: Gabriel Haselhurst | B34: 1 | C34: 1 | D34: 1 | E34: =(B34+C34)*$H$3+D34*$H$4 -> 87
A35: George Cooper | B35: 1 | E35: =(B35+C35)*$H$3+D35*$H$4 -> 32.5
A36: Harry Bannister | B36: 1 | E36: =(B36+C36)*$H$3+D36*$H$4 -> 32.5
A37: Harry Neal | B37: 1 | E37: =(B37+C37)*$H$3+D37*$H$4 -> 32.5
A38: Henry Forrest | B38: 1 | E38: =(B38+C38)*$H$3+D38*$H$4 -> 32.5
E39: =(B39+C39)*$H$3+D39*$H$4 -> 0
A40: Henry Murphy | B40: 1 | E40: =(B40+C40)*$H$3+D40*$H$4 -> 32.5
A41: Jack Lloyd | B41: 1 | C41: 1 | D41: 1 | E41: =(B41+C41)*$H$3+D41*$H$4 -> 87
...

Sheet Saxon Order
A1: Name | B1: Cost | C1: Quantity
A2: Andi Kapounek | B2: 56.2 | C2: 1
A3: Archie Jenkins | B3: 56.2 | C3: 1
A4: Ben Crook | B4: 56.2 | C4: 1
A5: Casey Mear | B5: 56.2 | C5: 1
A6: Don Lee | B6: 56.2 | C6: 1
A7: Felix McClean | B7: 56.2 | C7: 1
A8: Freddie McElwaine-Johnn | B8: 56.2 | C8: 1
A9: George Cooper | B9: 56.2 | C9: 1
A10: Harry Bannister | B10: 56.2 | C10: 1
A11: Jack Lloyd | B11: 56.2 | C11: 1
A12: Joseph Preddy | B12: 56.2 | C12: 1
A13: Jude Lipson | B13: 56.2 | C13: 1
... A20: Thomas Faulkner | B20: 56.2 | C20: 1

Sheet Y1 order
A1: Name | B1: Cost | C1: Size | D1: Initals (if desired) | E1: BLACK-BLUE-BLACK | F1: WHITE-BLUE-WHITE
A2: Sachin Bhogal | B2: 37.99 | C2: S | D2: SB | F2: 1
A3: Zack Fecher | B3: 37.99 | C3: M | D3: ZBF | E3: 1
A4: Archie Jenkins | B4: 37.99 | C4: M | D4: AWJ | F4: 1
A5: George Cooper | B5: 75.98 | C5: M | D5: GEC | E5: 1 | F5: 1

Sheet Notes
A1: TO DO
A2: Pay external umpires
A3: Get kit costs from Felix
A4: Get umpiring from Sam/Rhys
